// package java_engineering.exceptions;
//throw new exception_class("error message");  
public class throw_handle {
    static void fun()
    {
        try
        {
            throw new NullPointerException("demo");
        }
        catch(NullPointerException e)
        {
            System.out.println("Caught inside fun().");
            throw e; // rethrowing the exception
        }
    }
 
    public static void main(String args[])
    {
        try
        {
            fun();
        }
        catch(NullPointerException e)
        {
            System.out.println("Caught in main.");
        }
    }
}
